Workbook

Sheet Menu
B2: QUALITY AIRCRAFT ACCESSORIES
B3: A Hartzell Engine Technologies Company
B5: QUOTE SYSTEM v14.0
B7: QUOTE TYPES:
B8: 500HR SERVICE | C8: CUST PROPERTY | D8: EXCHANGE/SALE
B9: Magneto inspections | C9: Customer overhauls | D9: Exchange & inventory
B12: TOOLS & TRACKING
B13: Quote Tracker | C13: PO Tracking | D13: Infor XA Data | E13: Quick Reference
B14: Track follow-ups & status | C14: Order dates & YTD | D14: Import inventory | E14: How-to guides
B17: 5746 E Apache St, Tulsa, OK 74115 | 918-835-6948 | sales@qaainc.com

Sheet 500HR
B1: QUALITY AIRCRAFT ACCESSORIES
B2: 500HR MAGNETO INSPECTION SERVICE QUOTE
B4: Quote #: | C4: =Config!B2&"-"&TEXT(Config!B3,"00000") | E4: Date: | F4: 01/10/2026 | G4: Valid: | H4: 30 Days
B5: Order #: | E5: Customer PO #:
B6: Customer Email: | F6: Approval? | G6: No
B8: Magneto P/N | C8: Serial # | D8: Description | E8: 500HR $ | F8: Ovhl? | G8: CO Part# | H8: CO $ | I8: Total
D9: =IF(B9="","",IFERROR(VLOOKUP(B9&"5H",'Parts Master'!$A:$H,2,FALSE),IFERROR(VLOOKUP(B9,'Parts Master'!$A:$H,2,FALSE),"Not Found"))) | E9: =IF(B9="","",IFERROR(VLOOKUP(B9&"5H",'Parts Master'!$A:$H,4,FALSE),Config!$B$5)) | G9: =IF(F9="Yes",SUBSTITUTE(B9,"5H","")&"-CO","") | H9: =IF(G9="","",IFERROR(VLOOKUP(G9,'Parts Master'!$A:$H,4,FALSE),0)) | I9: =IF(B9="","",IF(F9="Yes",H9,E9))
D10: =IF(B10="","",IFERROR(VLOOKUP(B10&"5H",'Parts Master'!$A:$H,2,FALSE),IFERROR(VLOOKUP(B10,'Parts Master'!$A:$H,2,FALSE),"Not Found"))) | E10: =IF(B10="","",IFERROR(VLOOKUP(B10&"5H",'Parts Master'!$A:$H,4,FALSE),Config!$B$5)) | G10: =IF(F10="Yes",SUBSTITUTE(B10,"5H","")&"-CO","") | H10: =IF(G10="","",IFERROR(VLOOKUP(G10,'Parts Master'!$A:$H,4,FALSE),0)) | I10: =IF(B10="","",IF(F10="Yes",H10,E10))
D11: =IF(B11="","",IFERROR(VLOOKUP(B11&"5H",'Parts Master'!$A:$H,2,FALSE),IFERROR(VLOOKUP(B11,'Parts Master'!$A:$H,2,FALSE),"Not Found"))) | E11: =IF(B11="","",IFERROR(VLOOKUP(B11&"5H",'Parts Master'!$A:$H,4,FALSE),Config!$B$5)) | G11: =IF(F11="Yes",SUBSTITUTE(B11,"5H","")&"-CO","") | H11: =IF(G11="","",IFERROR(VLOOKUP(G11,'Parts Master'!$A:$H,4,FALSE),0)) | I11: =IF(B11="","",IF(F11="Yes",H11,E11))
D12: =IF(B12="","",IFERROR(VLOOKUP(B12&"5H",'Parts Master'!$A:$H,2,FALSE),IFERROR(VLOOKUP(B12,'Parts Master'!$A:$H,2,FALSE),"Not Found"))) | E12: =IF(B12="","",IFERROR(VLOOKUP(B12&"5H",'Parts Master'!$A:$H,4,FALSE),Config!$B$5)) | G12: =IF(F12="Yes",SUBSTITUTE(B12,"5H","")&"-CO","") | H12: =IF(G12="","",IFERROR(VLOOKUP(G12,'Parts Master'!$A:$H,4,FALSE),0)) | I12: =IF(B12="","",IF(F12="Yes",H12,E12))
D13: =IF(B13="","",IFERROR(VLOOKUP(B13&"5H",'Parts Master'!$A:$H,2,FALSE),IFERROR(VLOOKUP(B13,'Parts Master'!$A:$H,2,FALSE),"Not Found"))) | E13: =IF(B13="","",IFERROR(VLOOKUP(B13&"5H",'Parts Master'!$A:$H,4,FALSE),Config!$B$5)) | G13: =IF(F13="Yes",SUBSTITUTE(B13,"5H","")&"-CO","") | H13: =IF(G13="","",IFERROR(VLOOKUP(G13,'Parts Master'!$A:$H,4,FALSE),0)) | I13: =IF(B13="","",IF(F13="Yes",H13,E13))
D14: =IF(B14="","",IFERROR(VLOOKUP(B14&"5H",'Parts Master'!$A:$H,2,FALSE),IFERROR(VLOOKUP(B14,'Parts Master'!$A:$H,2,FALSE),"Not Found"))) | E14: =IF(B14="","",IFERROR(VLOOKUP(B14&"5H",'Parts Master'!$A:$H,4,FALSE),Config!$B$5)) | G14: =IF(F14="Yes",SUBSTITUTE(B14,"5H","")&"-CO","") | H14: =IF(G14="","",IFERROR(VLOOKUP(G14,'Parts Master'!$A:$H,4,FALSE),0)) | I14: =IF(B14="","",IF(F14="Yes",H14,E14))
B16: INSPECTION FINDINGS
B17: Coil | C17: Cap | D17: Dist | E17: Impulse | F17: Gear | G17: Points | H17: Brg | I17: Oil
B18: ☐ | C18: ☐ | D18: ☐ | E18: ☐ | F18: ☐ | G18: ☐ | H18: ☐ | I18: ☐
B19: ☐ | C19: ☐ | D19: ☐ | E19: ☐ | F19: ☐ | G19: ☐ | H19: ☐ | I19: ☐
B20: ☐ | C20: ☐ | D20: ☐ | E20: ☐ | F20: ☐ | G20: ☐ | H20: ☐ | I20: ☐
B21: ☐ | C21: ☐ | D21: ☐ | E21: ☐ | F21: ☐ | G21: ☐ | H21: ☐ | I21: ☐
B22: ☐ | C22: ☐ | D22: ☐ | E22: ☐ | F22: ☐ | G22: ☐ | H22: ☐ | I22: ☐
B23: ☐ | C23: ☐ | D23: ☐ | E23: ☐ | F23: ☐ | G23: ☐ | H23: ☐ | I23: ☐
B25: Findings Fee: | D25: =SUMPRODUCT((B18:I23<>"☐")*1)/8*Config!$B$6
F26: Service Total: | I26: =SUMIF(F9:F14,"<>Yes",E9:E14)
F27: Overhaul Total: | I27: =SUMIF(F9:F14,"Yes",H9:H14)
F28: GRAND TOTAL: | H28: =I26+I27+D25
B30: Notes:
B34: 5746 E Apache St, Tulsa, OK 74115 | 918-835-6948 | sales@qaainc.com | qaa.com

Sheet Cust Property
B1: QUALITY AIRCRAFT ACCESSORIES
B2: CUSTOMER PROPERTY OVERHAUL QUOTE
B4: Quote #: | C4: =Config!B2&"-"&TEXT(Config!B3,"00000") | E4: Date: | F4: 01/10/2026 | G4: Updated:
B5: Order #: | E5: Customer PO #:
B6: Customer Email: | F6: Tier: | G6: Standard
B7: Needs: | C7: Approval? | D7: No | E7: Ship? | F7: No | G7: Pay? | H7: No
B9: Unit P/N | C9: Description | D9: Type | E9: Base $ | F9: Your $ | G9: Exch Cap
C10: =IF(B10="","",IFERROR(VLOOKUP(B10,'Parts Master'!$A:$H,2,FALSE),"Not Found")) | D10: =IF(B10="","",IF(COUNTIF(BOM!$A:$A,SUBSTITUTE(B10,"-CO",""))>0,"In-House","Vendor")) | F10: =IF(E10="","",E10*(1-VLOOKUP($G$6,Config!$A$10:$B$13,2,FALSE))) | G10: =IF(B10="","",IFERROR(VLOOKUP(SUBSTITUTE(B10,"-CO","-OH"),'Parts Master'!$A:$H,4,FALSE),"N/A"))
C11: =IF(B11="","",IFERROR(VLOOKUP(B11,'Parts Master'!$A:$H,2,FALSE),"Not Found")) | D11: =IF(B11="","",IF(COUNTIF(BOM!$A:$A,SUBSTITUTE(B11,"-CO",""))>0,"In-House","Vendor")) | F11: =IF(E11="","",E11*(1-VLOOKUP($G$6,Config!$A$10:$B$13,2,FALSE))) | G11: =IF(B11="","",IFERROR(VLOOKUP(SUBSTITUTE(B11,"-CO","-OH"),'Parts Master'!$A:$H,4,FALSE),"N/A"))
C12: =IF(B12="","",IFERROR(VLOOKUP(B12,'Parts Master'!$A:$H,2,FALSE),"Not Found")) | D12: =IF(B12="","",IF(COUNTIF(BOM!$A:$A,SUBSTITUTE(B12,"-CO",""))>0,"In-House","Vendor")) | F12: =IF(E12="","",E12*(1-VLOOKUP($G$6,Config!$A$10:$B$13,2,FALSE))) | G12: =IF(B12="","",IFERROR(VLOOKUP(SUBSTITUTE(B12,"-CO","-OH"),'Parts Master'!$A:$H,4,FALSE),"N/A"))
C13: =IF(B13="","",IFERROR(VLOOKUP(B13,'Parts Master'!$A:$H,2,FALSE),"Not Found")) | D13: =IF(B13="","",IF(COUNTIF(BOM!$A:$A,SUBSTITUTE(B13,"-CO",""))>0,"In-House","Vendor")) | F13: =IF(E13="","",E13*(1-VLOOKUP($G$6,Config!$A$10:$B$13,2,FALSE))) | G13: =IF(B13="","",IFERROR(VLOOKUP(SUBSTITUTE(B13,"-CO","-OH"),'Parts Master'!$A:$H,4,FALSE),"N/A"))
B15: OVER & ABOVE PARTS
A16: # | B16: Part # | C16: Description | D16: Qty | E16: Unit $ | F16: Ext $ | G16: Status
C17: =IF(B17="","",IFERROR(VLOOKUP(B17,'Parts Master'!$A:$H,2,FALSE),"")) | E17: =IF(B17="","",IFERROR(VLOOKUP(B17,'Parts Master'!$A:$H,4,FALSE),0)) | F17: =IF(D17="","",E17*D17)
C18: =IF(B18="","",IFERROR(VLOOKUP(B18,'Parts Master'!$A:$H,2,FALSE),"")) | E18: =IF(B18="","",IFERROR(VLOOKUP(B18,'Parts Master'!$A:$H,4,FALSE),0)) | F18: =IF(D18="","",E18*D18)
C19: =IF(B19="","",IFERROR(VLOOKUP(B19,'Parts Master'!$A:$H,2,FALSE),"")) | E19: =IF(B19="","",IFERROR(VLOOKUP(B19,'Parts Master'!$A:$H,4,FALSE),0)) | F19: =IF(D19="","",E19*D19)
C20: =IF(B20="","",IFERROR(VLOOKUP(B20,'Parts Master'!$A:$H,2,FALSE),"")) | E20: =IF(B20="","",IFERROR(VLOOKUP(B20,'Parts Master'!$A:$H,4,FALSE),0)) | F20: =IF(D20="","",E20*D20)
C21: =IF(B21="","",IFERROR(VLOOKUP(B21,'Parts Master'!$A:$H,2,FALSE),"")) | E21: =IF(B21="","",IFERROR(VLOOKUP(B21,'Parts Master'!$A:$H,4,FALSE),0)) | F21: =IF(D21="","",E21*D21)
C22: =IF(B22="","",IFERROR(VLOOKUP(B22,'Parts Master'!$A:$H,2,FALSE),"")) | E22: =IF(B22="","",IFERROR(VLOOKUP(B22,'Parts Master'!$A:$H,4,FALSE),0)) | F22: =IF(D22="","",E22*D22)
C23: =IF(B23="","",IFERROR(VLOOKUP(B23,'Parts Master'!$A:$H,2,FALSE),"")) | E23: =IF(B23="","",IFERROR(VLOOKUP(B23,'Parts Master'!$A:$H,4,FALSE),0)) | F23: =IF(D23="","",E23*D23)
C24: =IF(B24="","",IFERROR(VLOOKUP(B24,'Parts Master'!$A:$H,2,FALSE),"")) | E24: =IF(B24="","",IFERROR(VLOOKUP(B24,'Parts Master'!$A:$H,4,FALSE),0)) | F24: =IF(D24="","",E24*D24)
E26: Labor: | F26: =SUM(F10:F13)
E27: Parts: | F27: =SUM(F17:F24)
E28: TOTAL: | F28: =F26+F27
B30: Notes:
B34: 918-835-6948 | sales@qaainc.com | qaa.com

Sheet Exchange
A1: QUALITY AIRCRAFT ACCESSORIES
A2: EXCHANGE / INVENTORY SALE QUOTE
A4: Quote #: | B4: =Config!B2&"-"&TEXT(Config!B3,"00000") | D4: Date: | E4: 01/10/2026 | G4: Valid: 30 Days
A5: Customer Email: | F5: Tier: | G5: Standard
A6: Approval? | B6: No | C6: Ship? | D6: No | E6: Pay? | F6: No | G6: Core In Hand? | H6: No
A8: Part # | B8: Description | C8: Cond | D8: Qty | E8: List $ | F8: Your $ | G8: Ext $ | H8: Core $ | I8: Stock | J8: Lead
B9: =IF(A9="","",IFERROR(VLOOKUP(A9,'Parts Master'!$A:$H,2,FALSE),"Not Found")) | C9: =IF(A9="","",IFERROR(VLOOKUP(A9,'Parts Master'!$A:$H,3,FALSE),"")) | E9: =IF(A9="","",IFERROR(VLOOKUP(A9,'Parts Master'!$A:$H,4,FALSE),0)) | F9: =IF(E9="","",E9*(1-VLOOKUP($G$5,Config!$A$10:$B$13,2,FALSE))) | G9: =IF(D9="","",F9*D9) | H9: =IF(A9="","",IF($H$6="Yes",0,IFERROR(VLOOKUP(A9,'Parts Master'!$A:$H,5,FALSE),0)*D9)) | I9: =IF(A9="","",IFERROR(VLOOKUP(A9,'Parts Master'!$A:$H,6,FALSE),"")) | J9: =IF(A9="","",IFERROR(VLOOKUP(A9,'Parts Master'!$A:$H,7,FALSE),""))
B10: =IF(A10="","",IFERROR(VLOOKUP(A10,'Parts Master'!$A:$H,2,FALSE),"Not Found")) | C10: =IF(A10="","",IFERROR(VLOOKUP(A10,'Parts Master'!$A:$H,3,FALSE),"")) | E10: =IF(A10="","",IFERROR(VLOOKUP(A10,'Parts Master'!$A:$H,4,FALSE),0)) | F10: =IF(E10="","",E10*(1-VLOOKUP($G$5,Config!$A$10:$B$13,2,FALSE))) | G10: =IF(D10="","",F10*D10) | H10: =IF(A10="","",IF($H$6="Yes",0,IFERROR(VLOOKUP(A10,'Parts Master'!$A:$H,5,FALSE),0)*D10)) | I10: =IF(A10="","",IFERROR(VLOOKUP(A10,'Parts Master'!$A:$H,6,FALSE),"")) | J10: =IF(A10="","",IFERROR(VLOOKUP(A10,'Parts Master'!$A:$H,7,FALSE),""))
B11: =IF(A11="","",IFERROR(VLOOKUP(A11,'Parts Master'!$A:$H,2,FALSE),"Not Found")) | C11: =IF(A11="","",IFERROR(VLOOKUP(A11,'Parts Master'!$A:$H,3,FALSE),"")) | E11: =IF(A11="","",IFERROR(VLOOKUP(A11,'Parts Master'!$A:$H,4,FALSE),0)) | F11: =IF(E11="","",E11*(1-VLOOKUP($G$5,Config!$A$10:$B$13,2,FALSE))) | G11: =IF(D11="","",F11*D11) | H11: =IF(A11="","",IF($H$6="Yes",0,IFERROR(VLOOKUP(A11,'Parts Master'!$A:$H,5,FALSE),0)*D11)) | I11: =IF(A11="","",IFERROR(VLOOKUP(A11,'Parts Master'!$A:$H,6,FALSE),"")) | J11: =IF(A11="","",IFERROR(VLOOKUP(A11,'Parts Master'!$A:$H,7,FALSE),""))
B12: =IF(A12="","",IFERROR(VLOOKUP(A12,'Parts Master'!$A:$H,2,FALSE),"Not Found")) | C12: =IF(A12="","",IFERROR(VLOOKUP(A12,'Parts Master'!$A:$H,3,FALSE),"")) | E12: =IF(A12="","",IFERROR(VLOOKUP(A12,'Parts Master'!$A:$H,4,FALSE),0)) | F12: =IF(E12="","",E12*(1-VLOOKUP($G$5,Config!$A$10:$B$13,2,FALSE))) | G12: =IF(D12="","",F12*D12) | H12: =IF(A12="","",IF($H$6="Yes",0,IFERROR(VLOOKUP(A12,'Parts Master'!$A:$H,5,FALSE),0)*D12)) | I12: =IF(A12="","",IFERROR(VLOOKUP(A12,'Parts Master'!$A:$H,6,FALSE),"")) | J12: =IF(A12="","",IFERROR(VLOOKUP(A12,'Parts Master'!$A:$H,7,FALSE),""))
B13: =IF(A13="","",IFERROR(VLOOKUP(A13,'Parts Master'!$A:$H,2,FALSE),"Not Found")) | C13: =IF(A13="","",IFERROR(VLOOKUP(A13,'Parts Master'!$A:$H,3,FALSE),"")) | E13: =IF(A13="","",IFERROR(VLOOKUP(A13,'Parts Master'!$A:$H,4,FALSE),0)) | F13: =IF(E13="","",E13*(1-VLOOKUP($G$5,Config!$A$10:$B$13,2,FALSE))) | G13: =IF(D13="","",F13*D13) | H13: =IF(A13="","",IF($H$6="Yes",0,IFERROR(VLOOKUP(A13,'Parts Master'!$A:$H,5,FALSE),0)*D13)) | I13: =IF(A13="","",IFERROR(VLOOKUP(A13,'Parts Master'!$A:$H,6,FALSE),"")) | J13: =IF(A13="","",IFERROR(VLOOKUP(A13,'Parts Master'!$A:$H,7,FALSE),""))
B14: =IF(A14="","",IFERROR(VLOOKUP(A14,'Parts Master'!$A:$H,2,FALSE),"Not Found")) | C14: =IF(A14="","",IFERROR(VLOOKUP(A14,'Parts Master'!$A:$H,3,FALSE),"")) | E14: =IF(A14="","",IFERROR(VLOOKUP(A14,'Parts Master'!$A:$H,4,FALSE),0)) | F14: =IF(E14="","",E14*(1-VLOOKUP($G$5,Config!$A$10:$B$13,2,FALSE))) | G14: =IF(D14="","",F14*D14) | H14: =IF(A14="","",IF($H$6="Yes",0,IFERROR(VLOOKUP(A14,'Parts Master'!$A:$H,5,FALSE),0)*D14)) | I14: =IF(A14="","",IFERROR(VLOOKUP(A14,'Parts Master'!$A:$H,6,FALSE),"")) | J14: =IF(A14="","",IFERROR(VLOOKUP(A14,'Parts Master'!$A:$H,7,FALSE),""))
B15: =IF(A15="","",IFERROR(VLOOKUP(A15,'Parts Master'!$A:$H,2,FALSE),"Not Found")) | C15: =IF(A15="","",IFERROR(VLOOKUP(A15,'Parts Master'!$A:$H,3,FALSE),"")) | E15: =IF(A15="","",IFERROR(VLOOKUP(A15,'Parts Master'!$A:$H,4,FALSE),0)) | F15: =IF(E15="","",E15*(1-VLOOKUP($G$5,Config!$A$10:$B$13,2,FALSE))) | G15: =IF(D15="","",F15*D15) | H15: =IF(A15="","",IF($H$6="Yes",0,IFERROR(VLOOKUP(A15,'Parts Master'!$A:$H,5,FALSE),0)*D15)) | I15: =IF(A15="","",IFERROR(VLOOKUP(A15,'Parts Master'!$A:$H,6,FALSE),"")) | J15: =IF(A15="","",IFERROR(VLOOKUP(A15,'Parts Master'!$A:$H,7,FALSE),""))
B16: =IF(A16="","",IFERROR(VLOOKUP(A16,'Parts Master'!$A:$H,2,FALSE),"Not Found")) | C16: =IF(A16="","",IFERROR(VLOOKUP(A16,'Parts Master'!$A:$H,3,FALSE),"")) | E16: =IF(A16="","",IFERROR(VLOOKUP(A16,'Parts Master'!$A:$H,4,FALSE),0)) | F16: =IF(E16="","",E16*(1-VLOOKUP($G$5,Config!$A$10:$B$13,2,FALSE))) | G16: =IF(D16="","",F16*D16) | H16: =IF(A16="","",IF($H$6="Yes",0,IFERROR(VLOOKUP(A16,'Parts Master'!$A:$H,5,FALSE),0)*D16)) | I16: =IF(A16="","",IFERROR(VLOOKUP(A16,'Parts Master'!$A:$H,6,FALSE),"")) | J16: =IF(A16="","",IFERROR(VLOOKUP(A16,'Parts Master'!$A:$H,7,FALSE),""))
B17: =IF(A17="","",IFERROR(VLOOKUP(A17,'Parts Master'!$A:$H,2,FALSE),"Not Found")) | C17: =IF(A17="","",IFERROR(VLOOKUP(A17,'Parts Master'!$A:$H,3,FALSE),"")) | E17: =IF(A17="","",IFERROR(VLOOKUP(A17,'Parts Master'!$A:$H,4,FALSE),0)) | F17: =IF(E17="","",E17*(1-VLOOKUP($G$5,Config!$A$10:$B$13,2,FALSE))) | G17: =IF(D17="","",F17*D17) | H17: =IF(A17="","",IF($H$6="Yes",0,IFERROR(VLOOKUP(A17,'Parts Master'!$A:$H,5,FALSE),0)*D17)) | I17: =IF(A17="","",IFERROR(VLOOKUP(A17,'Parts Master'!$A:$H,6,FALSE),"")) | J17: =IF(A17="","",IFERROR(VLOOKUP(A17,'Parts Master'!$A:$H,7,FALSE),""))
B18: =IF(A18="","",IFERROR(VLOOKUP(A18,'Parts Master'!$A:$H,2,FALSE),"Not Found")) | C18: =IF(A18="","",IFERROR(VLOOKUP(A18,'Parts Master'!$A:$H,3,FALSE),"")) | E18: =IF(A18="","",IFERROR(VLOOKUP(A18,'Parts Master'!$A:$H,4,FALSE),0)) | F18: =IF(E18="","",E18*(1-VLOOKUP($G$5,Config!$A$10:$B$13,2,FALSE))) | G18: =IF(D18="","",F18*D18) | H18: =IF(A18="","",IF($H$6="Yes",0,IFERROR(VLOOKUP(A18,'Parts Master'!$A:$H,5,FALSE),0)*D18)) | I18: =IF(A18="","",IFERROR(VLOOKUP(A18,'Parts Master'!$A:$H,6,FALSE),"")) | J18: =IF(A18="","",IFERROR(VLOOKUP(A18,'Parts Master'!$A:$H,7,FALSE),""))
A20: Subtotal: | B20: =SUM(G9:G18) | D20: Core: | E20: =SUM(H9:H18) | F20: =IF(H6="Yes","(WAIVED)","") | G20: Savings: | H20: =SUM(E9:E18)-SUM(F9:F18)
D21: GRAND TOTAL: | F21: =B20+IF(H6="Yes",0,E20)
A23: Notes:
A27: Core charges refunded upon receipt of serviceable core within 30 days.

Sheet Quote Tracker
A1: QUOTE TRACKER - Follow-up & Status Management
A2: RED = needs follow-up (7+ days) | Mark needs as DONE when fulfilled | Set Status to CLOSED when complete
A3: Quote # | B3: Created | C3: Customer Email | D3: Type | E3: Amount | F3: Approval | G3: Shipping | H3: Payment | I3: Reminders | J3: Last Contact | K3: Days | L3: Status | M3: Notes
K4: =IF(J4="","",TODAY()-J4)
K5: =IF(J5="","",TODAY()-J5)
K6: =IF(J6="","",TODAY()-J6)
K7: =IF(J7="","",TODAY()-J7)
K8: =IF(J8="","",TODAY()-J8)
K9: =IF(J9="","",TODAY()-J9)
K10: =IF(J10="","",TODAY()-J10)
K11: =IF(J11="","",TODAY()-J11)
K12: =IF(J12="","",TODAY()-J12)
K13: =IF(J13="","",TODAY()-J13)
K14: =IF(J14="","",TODAY()-J14)
K15: =IF(J15="","",TODAY()-J15)
... K53: =IF(J53="","",TODAY()-J53)
A55: Open: | B55: =COUNTIF(L4:L53,"OPEN") | C55: Need Follow-up: | D55: =SUMPRODUCT((L4:L53="OPEN")*(K4:K53>=7))

Sheet PO Tracking
A1: PO TRACKING - Create Date to Complete Date Analysis
A3: YTD SUMMARY
A4: Current Year: | B4: =YEAR(TODAY()) | C4: Previous Year: | D4: =YEAR(TODAY())-1
A5: YTD Orders: | B5: =COUNTIFS(D9:D500,">="&DATE(YEAR(TODAY()),1,1),D9:D500,"<="&TODAY()) | C5: YTD Completed: | D5: =COUNTIFS(E9:E500,">="&DATE(YEAR(TODAY()),1,1),E9:E500,"<="&TODAY())
A6: Avg Days to Complete: | B6: =IFERROR(AVERAGEIFS(F9:F500,F9:F500,">0",D9:D500,">="&DATE(YEAR(TODAY()),1,1)),0)
A8: PO # | B8: Order # | C8: Customer | D8: Create Date | E8: Complete Date | F8: Days | G8: Status | H8: Notes
F9: =IF(AND(D9<>"",E9<>""),E9-D9,IF(D9<>"",TODAY()-D9,""))
F10: =IF(AND(D10<>"",E10<>""),E10-D10,IF(D10<>"",TODAY()-D10,""))
F11: =IF(AND(D11<>"",E11<>""),E11-D11,IF(D11<>"",TODAY()-D11,""))
F12: =IF(AND(D12<>"",E12<>""),E12-D12,IF(D12<>"",TODAY()-D12,""))
F13: =IF(AND(D13<>"",E13<>""),E13-D13,IF(D13<>"",TODAY()-D13,""))
F14: =IF(AND(D14<>"",E14<>""),E14-D14,IF(D14<>"",TODAY()-D14,""))
F15: =IF(AND(D15<>"",E15<>""),E15-D15,IF(D15<>"",TODAY()-D15,""))
F16: =IF(AND(D16<>"",E16<>""),E16-D16,IF(D16<>"",TODAY()-D16,""))
F17: =IF(AND(D17<>"",E17<>""),E17-D17,IF(D17<>"",TODAY()-D17,""))
F18: =IF(AND(D18<>"",E18<>""),E18-D18,IF(D18<>"",TODAY()-D18,""))
F19: =IF(AND(D19<>"",E19<>""),E19-D19,IF(D19<>"",TODAY()-D19,""))
F20: =IF(AND(D20<>"",E20<>""),E20-D20,IF(D20<>"",TODAY()-D20,""))
... F108: =IF(AND(D108<>"",E108<>""),E108-D108,IF(D108<>"",TODAY()-D108,""))

Sheet Infor XA Data
A1: INFOR XA / MAPICS DATA IMPORT
A3: HOW TO UPDATE: Copy data from Infor XA Power Inquiry → Paste below → Data refreshes Parts Master
A4: No direct database connection = No IT security concerns. Manual paste is safe and controlled.
A6: Last Updated: | C6: Updated By: | E6: Version:
A8: Item # | B8: Description | C8: U/M | D8: On Hand | E8: Allocated | F8: Available | G8: Last Cost | H8: List Price | I8: Location
A109: ← Paste Infor XA data above (up to 100 rows) →

Sheet Quick Reference
B1: QUICK REFERENCE GUIDE
B3: 500HR SERVICE
B4: Enter Magneto P/N | C4: Type part number in column B (e.g., 10-382320)
B5: Price Lookup | C5: System auto-looks up 5H variant for 500HR price
B6: Mark Overhaul | C6: Set 'Ovhl?' to Yes if unit needs complete overhaul
B7: Findings | C7: Click checkboxes ☐→☑ for any issues found
B8: Generate PDF | C8: Click button or run GenPDF500HR macro
B9: Send Email | C9: Click button - auto-logs to Quote Tracker
B11: CUSTOMER PROPERTY
B12: Enter Unit P/N | C12: Use -CO suffix for customer overhaul parts
B13: Enter Base Price | C13: Manual entry - your labor quote
B14: Tier Discount | C14: Select customer tier for automatic discount
B15: O&A Parts | C15: Add over-and-above parts with quantities
B16: Order # / PO # | C16: Optional - shows on PDF if entered
B18: EXCHANGE / SALE
B19: Enter Part # | C19: Use -OH suffix for overhauled exchange units
B20: Core In Hand | C20: Set to Yes to waive core charges
B21: Quantity | C21: Enter qty - extended price auto-calculates
B22: Stock/Lead | C22: Auto-pulled from Parts Master
B24: QUOTE TRACKER
B25: Status | C25: OPEN = active, CLOSED = complete, ON HOLD = waiting
B26: Needs Columns | C26: Yes = needed, No = not needed, DONE = received
B27: Reminders | C27: Count of follow-up contacts made
B28: RED Row | C28: 7+ days since contact - needs follow-up!
B29: YELLOW Row | C29: 3-6 days - approaching follow-up time
B30: GREEN Row | C30: Quote is closed
B32: PO TRACKING
B33: Create Date | C33: When PO was created/received
B34: Complete Date | C34: When order shipped/completed
B35: Days | C35: Auto-calculated turnaround time
B36: YTD Stats | C36: Summary shows current year performance
B38: INFOR XA DATA
B39: Purpose | C39: Import inventory data without IT security issues
B40: How To | C40: Run Power Inquiry in XA → Copy results → Paste here
B41: Version | C41: Update 'Last Updated' and 'Version' after paste
B42: Refresh | C42: Parts Master can reference this for live stock levels
B44: PRO TIPS
B45: • | C45: Use Ctrl+; to enter today's date quickly
B46: • | C46: Filter Quote Tracker by Status to see only OPEN quotes
B47: • | C47: Check Quote Tracker weekly for RED rows needing follow-up
...

Sheet Parts Master
A1: Part Number | B1: Description | C1: Cond | D1: List Price | E1: Core Charge | F1: Stock | G1: Lead Time | H1: Notes
A2: 10-382320 | B2: S-20/200 Magneto | C2: Base | D2: 0 | E2: 0 | F2: 0 | H2: Base part
A3: 10-3823205H | B3: S-20/200 - 500HR Inspection | C3: Svc | D3: 575 | E3: 0 | F3: 0 | G3: 3-5 Days | H3: 500HR
A4: 10-382320-CO | B4: S-20/200 - Cust Overhaul | C4: CO | D4: 895 | E4: 0 | F4: 0 | G4: 7-10 Days
A5: 10-382320-OH | B5: S-20/200 - OH Exchange | C5: OH | D5: 2495 | E5: 1000 | F5: 5 | G5: 5-7 Days
A6: 10-320680 | B6: S-1200 Magneto | C6: Base | D6: 0 | E6: 0 | F6: 0 | H6: Base part
A7: 10-3206805H | B7: S-1200 - 500HR Inspection | C7: Svc | D7: 495 | E7: 0 | F7: 0 | G7: 3-5 Days | H7: 500HR
A8: 10-320680-CO | B8: S-1200 - Cust Overhaul | C8: CO | D8: 750 | E8: 0 | F8: 0 | G8: 7-10 Days
A9: 10-320680-OH | B9: S-1200 - OH Exchange | C9: OH | D9: 2095 | E9: 800 | F9: 3 | G9: 5-7 Days
A10: 10-391088 | B10: D-2000/D-3000 Magneto | C10: Base | D10: 0 | E10: 0 | F10: 0 | H10: Base part
A11: 10-3910885H | B11: D-2000/D-3000 - 500HR Inspection | C11: Svc | D11: 695 | E11: 0 | F11: 0 | G11: 3-5 Days | H11: 500HR
A12: 10-391088-CO | B12: D-2000/D-3000 - Cust Overhaul | C12: CO | D12: 1150 | E12: 0 | F12: 0 | G12: 7-10 Days
A13: 10-391088-OH | B13: D-2000/D-3000 - OH Exchange | C13: OH | D13: 2850 | E13: 1100 | F13: 2 | G13: 5-7 Days
A14: 10-163020 | B14: Bendix S-20 Magneto | C14: Base | D14: 0 | E14: 0 | F14: 0 | H14: Base part
A15: 10-1630205H | B15: Bendix S-20 - 500HR Inspection | C15: Svc | D15: 625 | E15: 0 | F15: 0 | G15: 3-5 Days | H15: 500HR
A16: 10-163020-CO | B16: Bendix S-20 - Cust Overhaul | C16: CO | D16: 950 | E16: 0 | F16: 0 | G16: 7-10 Days
A17: 10-163020-OH | B17: Bendix S-20 - OH Exchange | C17: OH | D17: 2650 | E17: 950 | F17: 4 | G17: 5-7 Days
A18: LW-15473 | B18: Impulse Coupling Assembly | C18: New | D18: 425 | E18: 0 | F18: 12 | G18: In Stock
A19: 10-357170 | B19: Coil Assembly | C19: New | D19: 185 | E19: 0 | F19: 20 | G19: In Stock
A20: 10-357210 | B20: Capacitor | C20: New | D20: 45 | E20: 0 | F20: 50 | G20: In Stock
A21: 10-51360 | B21: Distributor Block | C21: New | D21: 125 | E21: 0 | F21: 15 | G21: In Stock
A22: 10-51350 | B22: Points Assembly | C22: New | D22: 85 | E22: 0 | F22: 30 | G22: In Stock
A23: 10-51340 | B23: Bearing Set | C23: New | D23: 95 | E23: 0 | F23: 25 | G23: In Stock
A24: 646942-CO | B24: Governor - Cust Overhaul | C24: CO | D24: 1500 | E24: 0 | F24: 0 | G24: 14-21 Days | H24: Vendor
A25: 646942-OH | B25: Governor - OH Exchange | C25: OH | D25: 3450 | E25: 1500 | F25: 2 | G25: 5-7 Days
A26: 478615-CO | B26: Turbocharger - Cust Overhaul | C26: CO | D26: 2800 | E26: 0 | F26: 0 | G26: 21-30 Days | H26: Vendor
A27: 478615-OH | B27: Turbocharger - OH Exchange | C27: OH | D27: 5800 | E27: 2500 | F27: 1 | G27: 5-7 Days

Sheet BOM
A1: Parent P/N | B1: Description | C1: Component P/N | D1: Comp Desc | E1: Qty
A2: 10-382320 | B2: S-20/200 Magneto | C2: 10-357170 | D2: Coil Assembly | E2: 1
A3: 10-382320 | B3: S-20/200 Magneto | C3: 10-357210 | D3: Capacitor | E3: 1
A4: 10-382320 | B4: S-20/200 Magneto | C4: 10-51360 | D4: Distributor Block | E4: 1
A5: 10-320680 | B5: S-1200 Magneto | C5: 10-357170 | D5: Coil Assembly | E5: 1
A6: 10-391088 | B6: D-2000/D-3000 | C6: 10-357170 | D6: Coil Assembly | E6: 1

Sheet Config
A1: SYSTEM CONFIGURATION
A2: Quote Prefix | B2: QAA
A3: Next Quote # | B3: 1 | C3: Auto-increments
A4: Quote Valid Days | B4: 30
A5: 500HR Default Fee | B5: 550 | C5: Fallback
A6: 500HR Findings Fee | B6: 110 | C6: Per unit
A7: Reminder Days | B7: 7 | C7: Follow-up threshold
A9: TIER DISCOUNTS
A10: Standard | B10: 0
A11: Tier 1 | B11: 0.07
A12: Tier 2 | B12: 0.1
A13: Tier 3 | B13: 0.13
A15: VERSION INFO
A16: System Version: | B16: 14.0
A17: Last Updated: | B17: 01/10/2026
